Workbook

Sheet Tbl 1.2
A1: Employment Title | B1: 2024 National Employment Matrix (SOC) code | C1: SOC Code Category | D1: Occupation type | E1: AIOE | F1: Employment, 2024 | G1: Employment, 2034 | H1: Employment distribution, percent, 2024 | I1: Employment distribution, percent, 2034 | J1: Employment change, numeric, 2024–34 | K1: Employment change, percent, 2024–34 | L1: Percent self employed, 2024 | M1: Occupational openings, 2024–34 annual average | N1: Median annual wage, dollars, 2024[1] | O1: Wage Category | P1: Typical education needed for entry
A2: Education administrators, postsecondary | B2: 11-9033 | C2: 11 | D2: Line item | E2: 1.461149 | F2: 226.6 | G2: 230.5 | H2: 0.1 | I2: 0.1 | J2: 4 | K2: 1.7 | L2: 2.2 | M2: 15.1 | N2: 103960 | O2: {=_xlfn.IFS(N2<45000,"Under 45K",N2<75000,"45K - 75K",N2<100000,"75K - 100K",N2>=100000,"Over 100K")} -> Over 100K | P2: Master's degree
A3: Financial managers | B3: 11-3031 | C3: 11 | D3: Line item | E3: 1.446232 | F3: 868.6 | G3: 997.4 | H3: 0.5 | I3: 0.6 | J3: 128.8 | K3: 14.8 | L3: 2.4 | M3: 74.6 | N3: 161700 | O3: {=_xlfn.IFS(N3<45000,"Under 45K",N3<75000,"45K - 75K",N3<100000,"75K - 100K",N3>=100000,"Over 100K")} -> Over 100K | P3: Bachelor's degree
A4: Purchasing managers | B4: 11-3061 | C4: 11 | D4: Line item | E4: 1.423426 | F4: 83.5 | G4: 86.1 | H4: 0 | I4: 0 | J4: 2.6 | K4: 3.1 | L4: 0.8 | M4: 6.4 | N4: 139510 | O4: {=_xlfn.IFS(N4<45000,"Under 45K",N4<75000,"45K - 75K",N4<100000,"75K - 100K",N4>=100000,"Over 100K")} -> Over 100K | P4: Bachelor's degree
A5: Chief executives | B5: 11-1011 | C5: 11 | D5: Line item | E5: 1.334246 | F5: 309.4 | G5: 322.7 | H5: 0.2 | I5: 0.2 | J5: 13.3 | K5: 4.3 | L5: 25.9 | M5: 22.2 | N5: 206420 | O5: {=_xlfn.IFS(N5<45000,"Under 45K",N5<75000,"45K - 75K",N5<100000,"75K - 100K",N5>=100000,"Over 100K")} -> Over 100K | P5: Bachelor's degree
A6: Natural sciences managers | B6: 11-9121 | C6: 11 | D6: Line item | E6: 1.327906 | F6: 104.3 | G6: 108.2 | H6: 0.1 | I6: 0.1 | J6: 3.9 | K6: 3.7 | L6: — | M6: 8.5 | N6: 161180 | O6: {=_xlfn.IFS(N6<45000,"Under 45K",N6<75000,"45K - 75K",N6<100000,"75K - 100K",N6>=100000,"Over 100K")} -> Over 100K | P6: Bachelor's degree
A7: Human resources managers | B7: 11-3121 | C7: 11 | D7: Line item | E7: 1.320417 | F7: 221.9 | G7: 233 | H7: 0.1 | I7: 0.1 | J7: 11.1 | K7: 5 | L7: 0.6 | M7: 17.9 | N7: 140030 | O7: {=_xlfn.IFS(N7<45000,"Under 45K",N7<75000,"45K - 75K",N7<100000,"75K - 100K",N7>=100000,"Over 100K")} -> Over 100K | P7: Bachelor's degree
A8: Marketing managers | B8: 11-2021 | C8: 11 | D8: Line item | E8: 1.315032 | F8: 407 | G8: 433.7 | H8: 0.2 | I8: 0.2 | J8: 26.7 | K8: 6.6 | L8: 3.6 | M8: 34.3 | N8: 161030 | O8: {=_xlfn.IFS(N8<45000,"Under 45K",N8<75000,"45K - 75K",N8<100000,"75K - 100K",N8>=100000,"Over 100K")} -> Over 100K | P8: Bachelor's degree
A9: Compensation and benefits managers | B9: 11-3111 | C9: 11 | D9: Line item | E9: 1.298235 | F9: 20.9 | G9: 20.9 | H9: 0 | I9: 0 | J9: 0 | K9: 0.2 | L9: 1.4 | M9: 1.5 | N9: 140360 | O9: {=_xlfn.IFS(N9<45000,"Under 45K",N9<75000,"45K - 75K",N9<100000,"75K - 100K",N9>=100000,"Over 100K")} -> Over 100K | P9: Bachelor's degree
A10: Advertising and promotions managers | B10: 11-2011 | C10: 11 | D10: Line item | E10: 1.294387 | F10: 27 | G10: 26.4 | H10: 0 | I10: 0 | J10: -0.6 | K10: -2.2 | L10: 20.7 | M10: 2.1 | N10: 126960 | O10: {=_xlfn.IFS(N10<45000,"Under 45K",N10<75000,"45K - 75K",N10<100000,"75K - 100K",N10>=100000,"Over 100K")} -> Over 100K | P10: Bachelor's degree
A11: Training and development managers | B11: 11-3131 | C11: 11 | D11: Line item | E11: 1.284423 | F11: 46.4 | G11: 49.2 | H11: 0 | I11: 0 | J11: 2.7 | K11: 5.8 | L11: — | M11: 3.8 | N11: 127090 | O11: {=_xlfn.IFS(N11<45000,"Under 45K",N11<75000,"45K - 75K",N11<100000,"75K - 100K",N11>=100000,"Over 100K")} -> Over 100K | P11: Bachelor's degree
A12: Sales managers | B12: 11-2022 | C12: 11 | D12: Line item | E12: 1.26628 | F12: 619.5 | G12: 648.5 | H12: 0.4 | I12: 0.4 | J12: 29 | K12: 4.7 | L12: 0.9 | M12: 49 | N12: 138060 | O12: {=_xlfn.IFS(N12<45000,"Under 45K",N12<75000,"45K - 75K",N12<100000,"75K - 100K",N12>=100000,"Over 100K")} -> Over 100K | P12: Bachelor's degree
A13: Medical and health services managers | B13: 11-9111 | C13: 11 | D13: Line item | E13: 1.260259 | F13: 616.2 | G13: 759.1 | H13: 0.4 | I13: 0.4 | J13: 142.9 | K13: 23.2 | L13: 5.1 | M13: 62.1 | N13: 117960 | O13: {=_xlfn.IFS(N13<45000,"Under 45K",N13<75000,"45K - 75K",N13<100000,"75K - 100K",N13>=100000,"Over 100K")} -> Over 100K | P13: Bachelor's degree
A14: Property, real estate, and community association managers | B14: 11-9141 | C14: 11 | D14: Line item | E14: 1.215396 | F14: 466.1 | G14: 483.1 | H14: 0.3 | I14: 0.3 | J14: 17 | K14: 3.6 | L14: 34 | M14: 39 | N14: 66700 | O14: {=_xlfn.IFS(N14<45000,"Under 45K",N14<75000,"45K - 75K",N14<100000,"75K - 100K",N14>=100000,"Over 100K")} -> 45K - 75K | P14: High school diploma or equivalent
A15: Social and community service managers | B15: 11-9151 | C15: 11 | D15: Line item | E15: 1.156153 | F15: 219.8 | G15: 233.9 | H15: 0.1 | I15: 0.1 | J15: 14.1 | K15: 6.4 | L15: 5.6 | M15: 18.6 | N15: 78240 | O15: {=_xlfn.IFS(N15<45000,"Under 45K",N15<75000,"45K - 75K",N15<100000,"75K - 100K",N15>=100000,"Over 100K")} -> 75K - 100K | P15: Bachelor's degree
A16: Computer and information systems managers | B16: 11-3021 | C16: 11 | D16: Line item | E16: 1.059853 | F16: 667.1 | G16: 768.7 | H16: 0.4 | I16: 0.4 | J16: 101.6 | K16: 15.2 | L16: 0.9 | M16: 55.6 | N16: 171200 | O16: {=_xlfn.IFS(N16<45000,"Under 45K",N16<75000,"45K - 75K",N16<100000,"75K - 100K",N16>=100000,"Over 100K")} -> Over 100K | P16: Bachelor's degree
A17: Education administrators, kindergarten through secondary | B17: 11-9032 | C17: 11 | D17: Line item | E17: 1.048811 | F17: 333.3 | G17: 328.1 | H17: 0.2 | I17: 0.2 | J17: -5.1 | K17: -1.5 | L17: 1.2 | M17: 20.8 | N17: 104070 | O17: {=_xlfn.IFS(N17<45000,"Under 45K",N17<75000,"45K - 75K",N17<100000,"75K - 100K",N17>=100000,"Over 100K")} -> Over 100K | P17: Master's degree
A18: Emergency management directors | B18: 11-9161 | C18: 11 | D18: Line item | E18: 1.030768 | F18: 13.2 | G18: 13.6 | H18: 0 | I18: 0 | J18: 0.4 | K18: 3 | L18: — | M18: 1 | N18: 86130 | O18: {=_xlfn.IFS(N18<45000,"Under 45K",N18<75000,"45K - 75K",N18<100000,"75K - 100K",N18>=100000,"Over 100K")} -> 75K - 100K | P18: Bachelor's degree
A19: Construction managers | B19: 11-9021 | C19: 11 | D19: Line item | E19: 1.029139 | F19: 550.3 | G19: 598.4 | H19: 0.3 | I19: 0.3 | J19: 48.1 | K19: 8.7 | L19: 35.8 | M19: 46.8 | N19: 106980 | O19: {=_xlfn.IFS(N19<45000,"Under 45K",N19<75000,"45K - 75K",N19<100000,"75K - 100K",N19>=100000,"Over 100K")} -> Over 100K | P19: Bachelor's degree
A20: Managers, all other | B20: 11-9199 | C20: 11 | D20: Line item | E20: 0.9646872 | F20: 1333.7 | G20: 1393.5 | H20: 0.8 | I20: 0.8 | J20: 59.8 | K20: 4.5 | L20: 48.6 | M20: 106.7 | N20: 136550 | O20: {=_xlfn.IFS(N20<45000,"Under 45K",N20<75000,"45K - 75K",N20<100000,"75K - 100K",N20>=100000,"Over 100K")} -> Over 100K | P20: Bachelor's degree
A21: Transportation, storage, and distribution managers | B21: 11-3071 | C21: 11 | D21: Line item | E21: 0.8907923 | F21: 216.7 | G21: 229.8 | H21: 0.1 | I21: 0.1 | J21: 13.1 | K21: 6.1 | L21: 1.7 | M21: 18.5 | N21: 102010 | O21: {=_xlfn.IFS(N21<45000,"Under 45K",N21<75000,"45K - 75K",N21<100000,"75K - 100K",N21>=100000,"Over 100K")} -> Over 100K | P21: High school diploma or equivalent
A22: Education and childcare administrators, preschool and daycare | B22: 11-9031 | C22: 11 | D22: Line item | E22: 0.838007 | F22: 90.2 | G22: 87.9 | H22: 0.1 | I22: 0.1 | J22: -2.3 | K22: -2.5 | L22: 4.9 | M22: 5.5 | N22: 56270 | O22: {=_xlfn.IFS(N22<45000,"Under 45K",N22<75000,"45K - 75K",N22<100000,"75K - 100K",N22>=100000,"Over 100K")} -> 45K - 75K | P22: Bachelor's degree
A23: Architectural and engineering managers | B23: 11-9041 | C23: 11 | D23: Line item | E23: 0.8370105 | F23: 212.5 | G23: 220.5 | H23: 0.1 | I23: 0.1 | J23: 8 | K23: 3.8 | L23: 0.2 | M23: 14.5 | N23: 167740 | O23: {=_xlfn.IFS(N23<45000,"Under 45K",N23<75000,"45K - 75K",N23<100000,"75K - 100K",N23>=100000,"Over 100K")} -> Over 100K | P23: Bachelor's degree
A24: Gambling managers | B24: 11-9071 | C24: 11 | D24: Line item | E24: 0.8299207 | F24: 5.1 | G24: 5.2 | H24: 0 | I24: 0 | J24: 0.1 | K24: 1.2 | L24: 7.7 | M24: 0.6 | N24: 85580 | O24: {=_xlfn.IFS(N24<45000,"Under 45K",N24<75000,"45K - 75K",N24<100000,"75K - 100K",N24>=100000,"Over 100K")} -> 75K - 100K | P24: High school diploma or equivalent
A25: Postmasters and mail superintendents | B25: 11-9131 | C25: 11 | D25: Line item | E25: 0.8233757 | F25: 13.1 | G25: 12.7 | H25: 0 | I25: 0 | J25: -0.5 | K25: -3.5 | L25: — | M25: 0.9 | N25: 92730 | O25: {=_xlfn.IFS(N25<45000,"Under 45K",N25<75000,"45K - 75K",N25<100000,"75K - 100K",N25>=100000,"Over 100K")} -> 75K - 100K | P25: High school diploma or equivalent
A26: General and operations managers | B26: 11-1021 | C26: 11 | D26: Line item | E26: 0.5748773 | F26: 3712.9 | G26: 3876.8 | H26: 2.2 | I26: 2.2 | J26: 164 | K26: 4.4 | L26: 0.9 | M26: 308.7 | N26: 102950 | O26: {=_xlfn.IFS(N26<45000,"Under 45K",N26<75000,"45K - 75K",N26<100000,"75K - 100K",N26>=100000,"Over 100K")} -> Over 100K | P26: Bachelor's degree
A27: Industrial production managers | B27: 11-3051 | C27: 11 | D27: Line item | E27: 0.5086878 | F27: 241.9 | G27: 246.5 | H27: 0.1 | I27: 0.1 | J27: 4.6 | K27: 1.9 | L27: 2.6 | M27: 17.1 | N27: 121440 | O27: {=_xlfn.IFS(N27<45000,"Under 45K",N27<75000,"45K - 75K",N27<100000,"75K - 100K",N27>=100000,"Over 100K")} -> Over 100K | P27: Bachelor's degree
A28: Lodging managers | B28: 11-9081 | C28: 11 | D28: Line item | E28: 0.4021726 | F28: 52 | G28: 53.8 | H28: 0 | I28: 0 | J28: 1.8 | K28: 3.4 | L28: 19.1 | M28: 5.4 | N28: 68130 | O28: {=_xlfn.IFS(N28<45000,"Under 45K",N28<75000,"45K - 75K",N28<100000,"75K - 100K",N28>=100000,"Over 100K")} -> 45K - 75K | P28: High school diploma or equivalent
A29: Education administrators, all other | B29: 11-9039 | C29: 11 | D29: Line item | E29: 0.3541265 | F29: 60.2 | G29: 61.7 | H29: 0 | I29: 0 | J29: 1.5 | K29: 2.5 | L29: 3.5 | M29: 4.1 | N29: 89040 | O29: {=_xlfn.IFS(N29<45000,"Under 45K",N29<75000,"45K - 75K",N29<100000,"75K - 100K",N29>=100000,"Over 100K")} -> 75K - 100K | P29: Bachelor's degree
A30: Legislators | B30: 11-1031 | C30: 11 | D30: Line item | E30: 0 | F30: 27.7 | G30: 28.6 | H30: 0 | I30: 0 | J30: 0.9 | K30: 3.4 | L30: — | M30: 2.2 | N30: 44810 | O30: {=_xlfn.IFS(N30<45000,"Under 45K",N30<75000,"45K - 75K",N30<100000,"75K - 100K",N30>=100000,"Over 100K")} -> Under 45K | P30: Bachelor's degree
A31: Public relations managers | B31: 11-2032 | C31: 11 | D31: Line item | E31: 0 | F31: 83.2 | G31: 87.3 | H31: 0 | I31: 0 | J31: 4.1 | K31: 5 | L31: 0.3 | M31: 6.6 | N31: 138520 | O31: {=_xlfn.IFS(N31<45000,"Under 45K",N31<75000,"45K - 75K",N31<100000,"75K - 100K",N31>=100000,"Over 100K")} -> Over 100K | P31: Bachelor's degree
A32: Fundraising managers | B32: 11-2033 | C32: 11 | D32: Line item | E32: 0 | F32: 45.7 | G32: 47.6 | H32: 0 | I32: 0 | J32: 1.9 | K32: 4.2 | L32: 0.2 | M32: 3.6 | N32: 123480 | O32: {=_xlfn.IFS(N32<45000,"Under 45K",N32<75000,"45K - 75K",N32<100000,"75K - 100K",N32>=100000,"Over 100K")} -> Over 100K | P32: Bachelor's degree
A33: Administrative services managers | B33: 11-3012 | C33: 11 | D33: Line item | E33: 0 | F33: 271.2 | G33: 283.8 | H33: 0.2 | I33: 0.2 | J33: 12.6 | K33: 4.6 | L33: 0 | M33: 23.2 | N33: 108390 | O33: {=_xlfn.IFS(N33<45000,"Under 45K",N33<75000,"45K - 75K",N33<100000,"75K - 100K",N33>=100000,"Over 100K")} -> Over 100K | P33: Bachelor's degree
A34: Facilities managers | B34: 11-3013 | C34: 11 | D34: Line item | E34: 0 | F34: 151.4 | G34: 157.1 | H34: 0.1 | I34: 0.1 | J34: 5.7 | K34: 3.8 | L34: — | M34: 13.2 | N34: 104690 | O34: {=_xlfn.IFS(N34<45000,"Under 45K",N34<75000,"45K - 75K",N34<100000,"75K - 100K",N34>=100000,"Over 100K")} -> Over 100K | P34: Bachelor's degree
A35: Entertainment and recreation managers, except gambling | B35: 11-9072 | C35: 11 | D35: Line item | E35: 0 | F35: 43.2 | G35: 46.5 | H35: 0 | I35: 0 | J35: 3.3 | K35: 7.7 | L35: 8.6 | M35: 5.5 | N35: 77180 | O35: {=_xlfn.IFS(N35<45000,"Under 45K",N35<75000,"45K - 75K",N35<100000,"75K - 100K",N35>=100000,"Over 100K")} -> 75K - 100K | P35: Bachelor's degree
A36: Funeral home managers | B36: 11-9171 | C36: 11 | D36: Line item | E36: 0 | F36: 32.1 | G36: 33.4 | H36: 0 | I36: 0 | J36: 1.3 | K36: 4.1 | L36: 56.1 | M36: 2.6 | N36: 76830 | O36: {=_xlfn.IFS(N36<45000,"Under 45K",N36<75000,"45K - 75K",N36<100000,"75K - 100K",N36>=100000,"Over 100K")} -> 75K - 100K | P36: Associate's degree
A37: Personal service managers, all other | B37: 11-9179 | C37: 11 | D37: Line item | E37: 0 | F37: 25.1 | G37: 26.7 | H37: 0 | I37: 0 | J37: 1.6 | K37: 6.5 | L37: 54.3 | M37: 2.1 | N37: 61340 | O37: {=_xlfn.IFS(N37<45000,"Under 45K",N37<75000,"45K - 75K",N37<100000,"75K - 100K",N37>=100000,"Over 100K")} -> 45K - 75K | P37: High school diploma or equivalent
A38: Food service managers | B38: 11-9051 | C38: 11 | D38: Line item | E38: -0.1213112 | F38: 352.8 | G38: 375.3 | H38: 0.2 | I38: 0.2 | J38: 22.6 | K38: 6.4 | L38: 30.3 | M38: 42 | N38: 65310 | O38: {=_xlfn.IFS(N38<45000,"Under 45K",N38<75000,"45K - 75K",N38<100000,"75K - 100K",N38>=100000,"Over 100K")} -> 45K - 75K | P38: High school diploma or equivalent
A39: Farmers, ranchers, and other agricultural managers | B39: 11-9013 | C39: 11 | D39: Line item | E39: -0.1443684 | F39: 836.1 | G39: 825 | H39: 0.5 | I39: 0.5 | J39: -11.1 | K39: -1.3 | L39: 62.6 | M39: 85.5 | N39: 87980 | O39: {=_xlfn.IFS(N39<45000,"Under 45K",N39<75000,"45K - 75K",N39<100000,"75K - 100K",N39>=100000,"Over 100K")} -> 75K - 100K | P39: High school diploma or equivalent
A40: Financial examiners | B40: 13-2061 | C40: 13 | D40: Line item | E40: 1.526064 | F40: 65.1 | G40: 77.2 | H40: 0 | I40: 0 | J40: 12.1 | K40: 18.5 | L40: 0.4 | M40: 5.7 | N40: 90400 | O40: {=_xlfn.IFS(N40<45000,"Under 45K",N40<75000,"45K - 75K",N40<100000,"75K - 100K",N40>=100000,"Over 100K")} -> 75K - 100K | P40: Bachelor's degree
...

Sheet Education Analysis
A3: Typical education needed for entry | B3: Average of AIOE | C3: Average of Employment change, percent, 2024–34 | F3: Req. Educ | G3: Avg AIOE
A4: Associate's degree | B4: 0.11000384 | C4: 3.075 | F4: Master's | G4: 0.7691541
A5: Bachelor's degree | B5: 0.72416889 | C5: 4.1533708 | F5: PhD/Prof | G5: 0.73184606
A6: Doctoral or professional degree | B6: 0.73184606 | C6: 4.0452055 | F6: Bachelor's | G6: 0.72416889
A7: High school diploma or equivalent | B7: -0.36827607 | C7: -0.81840491 | F7: Some college | G7: 0.24170056
A8: Master's degree | B8: 0.7691541 | C8: 7.245 | F8: Associate's | G8: 0.11000384
A9: No formal educational credential | B9: -0.89510787 | C9: 0.26605505 | F9: Postsecondary | G9: -0.34911962
A10: Postsecondary nondegree award | B10: -0.34911962 | C10: 4.8156863 | F10: HS diploma | G10: -0.36827607
A11: Some college, no degree | B11: 0.24170056 | C11: -4.0285714 | F11: No formal | G11: -0.89510787
A12: Grand Total | B12: -0.018467281 | C12: 1.7447115

Sheet Wage Analysis
A1: Wage Range | B1: Count of Occupations | C1: Avg. AIOE | D1: Avg. AIOE ; AIOE > 0 | E1: Avg. % Growth | G1: Wage Range | H1: Avg AIOE | I1: Avg % Growth
A2: Under 45K | B2: =COUNTIF('Tbl 1.2'!N:N, "<45000") -> 184 | C2: =AVERAGEIFS('Tbl 1.2'!E:E, 'Tbl 1.2'!N:N, "<45000") -> -0.4618159 | D2: =AVERAGEIFS('Tbl 1.2'!E:E, 'Tbl 1.2'!N:N, "<45000", 'Tbl 1.2'!E:E, ">0") -> 0.5272374 | E2: =AVERAGEIF('Tbl 1.2'!O:O,A2,'Tbl 1.2'!K:K) -> -0.25163043 | G2: Under 45K | H2: -0.46182 | I2: -0.25163
A3: 45K - 75K | B3: =COUNTIFS('Tbl 1.2'!N:N, ">=45000", 'Tbl 1.2'!N:N, "<75000") -> 389 | C3: =AVERAGEIFS('Tbl 1.2'!E:E, 'Tbl 1.2'!N:N, ">=45000", 'Tbl 1.2'!N:N, "<75000") -> -0.21607648 | D3: =AVERAGEIFS('Tbl 1.2'!E:E, 'Tbl 1.2'!N:N, ">=45000", 'Tbl 1.2'!N:N, "<75000", 'Tbl 1.2'!E:E, ">0") -> 0.85050101 | E3: =AVERAGEIF('Tbl 1.2'!O:O,A3,'Tbl 1.2'!K:K) -> 0.88508997 | G3: 45K-75K | H3: -0.21608 | I3: 0.88509
A4: 75K - 100K | B4: =COUNTIFS('Tbl 1.2'!N:N, ">=75000", 'Tbl 1.2'!N:N, "<100000") -> 126 | C4: =AVERAGEIFS('Tbl 1.2'!E:E, 'Tbl 1.2'!N:N, ">=75000", 'Tbl 1.2'!N:N, "<100000") -> 0.59035071 | D4: =AVERAGEIFS('Tbl 1.2'!E:E, 'Tbl 1.2'!N:N, ">=75000", 'Tbl 1.2'!N:N, "<100000", 'Tbl 1.2'!E:E, ">0") -> 1.0325183 | E4: =AVERAGEIF('Tbl 1.2'!O:O,A4,'Tbl 1.2'!K:K) -> 3.434127 | G4: 75K-100K | H4: 0.590351 | I4: 3.434127
A5: Over 100K | B5: =COUNTIFS('Tbl 1.2'!N:N, ">=100000") -> 110 | C5: =AVERAGEIFS('Tbl 1.2'!E:E, 'Tbl 1.2'!N:N, ">100000") -> 0.74570021 | D5: =AVERAGEIFS('Tbl 1.2'!E:E, 'Tbl 1.2'!N:N, ">100000", 'Tbl 1.2'!E:E, ">0") -> 1.0946261 | E5: =AVERAGEIF('Tbl 1.2'!O:O,A5,'Tbl 1.2'!K:K) -> 5.4203008 | G5: Over 100K | H5: 0.7457 | I5: 5.420301

Sheet Avg AIOE by SOC Category
A1: SOC Code Category | B1: Average of AIOE | C1: Average of Employment change, numeric, 2024–34 | D1: Average of Employment change, percent, 2024–34 | F1: SOC Code | G1: AVG AIOE
A2: 23 | B2: 1.2083207 | C2: 4.8 | D2: 1.7125 | F2: 23 | G2: 1.2083207 | S2: SOC Category Reference Key
A3: 13 | B3: 1.0484 | C3: 18.33125 | D3: 4.1125 | F3: 13 | G3: 1.0484 | R3: High AIOE/Cognitive | T3: Low AIOE/ Physical & Care Based
A4: 25 | B4: 0.84794969 | C4: 0.9703125 | D4: 1.9125 | F4: 25 | G4: 0.84794969 | R4: 23:Legal | T4: 29:Healthcare Prac
A5: 11 | B5: 0.77184447 | C5: 21.934211 | D5: 4.5394737 | F5: 11 | G5: 0.77184447 | R5: 13:Business & Finance | T5: 31: Healthcare Support
A6: 17 | B6: 0.76335121 | C6: 3.8888889 | D6: 3.2555556 | F6: 17 | G6: 0.76335121 | R6: 15: Computer & Math | T6: 35: Food Prep & Service
A7: 19 | B7: 0.70422783 | C7: 1.68125 | D7: 3.3833333 | F7: 19 | G7: 0.70422783 | R7: 25: Educational/Inst. | T7: 47: Construction
A8: 43 | B8: 0.6227622 | C8: -14.109259 | D8: -6.3962963 | F8: 43 | G8: 0.6227622 | R8: 43: Office & Admin | T8: 51: Production
A9: 21 | B9: 0.58164399 | C9: 12.482353 | D9: 6.1588235 | F9: 21 | G9: 0.58164399
A10: 41 | B10: 0.5490306 | C10: -13.536364 | D10: -1.1136364 | F10: 41 | G10: 0.5490306
A11: 15 | B11: 0.2748351 | C11: 25.985714 | D11: 9.6095238 | F11: 15 | G11: 0.2748351
A12: 27 | B12: 0.13875208 | C12: 2.0365854 | D12: 1.7073171 | F12: 27 | G12: 0.13875208
A13: 29 | B13: 0.056833938 | C13: 10.242254 | D13: 7.115493 | F13: 29 | G13: 0.056833938
A14: 31 | B14: -0.29401576 | C14: 58.135294 | D14: 7.4 | F14: 31 | G14: -0.29401576
A15: 33 | B15: -0.31416233 | C15: 1.2083333 | D15: 1.3041667 | F15: 33 | G15: -0.31416233
A16: 39 | B16: -0.3242978 | C16: 5.825 | D16: 3.8 | F16: 39 | G16: -0.3242978
A17: 53 | B17: -0.55919109 | C17: 11.59 | D17: 2.318 | F17: 53 | G17: -0.55919109
A18: 35 | B18: -0.66095135 | C18: 28.823529 | D18: 2.5764706 | F18: 35 | G18: -0.66095135
A19: 51 | B19: -0.74760733 | C19: -0.95047619 | D19: -4.9904762 | F19: 51 | G19: -0.74760733
A20: 45 | B20: -0.77993136 | C20: -1.8 | D20: -1.4785714 | F20: 45 | G20: -0.77993136
... A24: Grand Total | B24: -0.018467281 | C24: 6.2628606 | D24: 1.7447115 | F24: Grand Total | G24: -0.018467281
F26: SOC Code | G26: %Avg Change '24-'24
F27: 23 | G27: 1.7125
F28: 13 | G28: 4.1125
F29: 25 | G29: 1.9125
F30: 11 | G30: 4.5394737
F31: 17 | G31: 3.2555556
F32: 19 | G32: 3.3833333
F33: 43 | G33: -6.3962963
F34: 21 | G34: 6.1588235
F35: 41 | G35: -1.1136364
F36: 15 | G36: 9.6095238
F37: 27 | G37: 1.7073171
F38: 29 | G38: 7.115493
... F48: 47 | G48: 1.87

Sheet AIOE Appendix A
A1: SOC Code | B1: Occupation Title | C1: AIOE
A2: 11-1011 | B2: Chief Executives | C2: 1.334246
A3: 11-1021 | B3: General and Operations Managers | C3: 0.5748773
A4: 11-2011 | B4: Advertising and Promotions Managers | C4: 1.294387
A5: 11-2021 | B5: Marketing Managers | C5: 1.315032
A6: 11-2022 | B6: Sales Managers | C6: 1.26628
A7: 11-2031 | B7: Public Relations Managers | C7: 1.293689
A8: 11-3011 | B8: Administrative Services Managers | C8: 0.7398278
A9: 11-3021 | B9: Computer and Information Systems Managers | C9: 1.059853
A10: 11-3031 | B10: Financial Managers | C10: 1.446232
A11: 11-3051 | B11: Industrial Production Managers | C11: 0.5086878
A12: 11-3061 | B12: Purchasing Managers | C12: 1.423426
A13: 11-3071 | B13: Transportation, Storage, and Distribution Managers | C13: 0.8907923
... A775: 53-7121 | B775: Tank Car, Truck, and Ship Loaders | C775: -1.38776
